<?xml version="1.0" encoding="utf-8" ?>
<!-- =================================================================================== -->
<!-- |    This document was autogenerated by xacro from /home/goksel/GitHub/IntroToRobotics/myrobotws/src/my_pr_robot/urdf/pr_robot_links_and_joints.xacro | -->
<!-- |    EDITING THIS FILE BY HAND IS NOT RECOMMENDED                                 | -->
<!-- =================================================================================== -->
<robot name="pr_robot">
    <!-- END - Include -->
    <link name="base_link">
        <collision>
            <origin rpy="0 0 0" xyz="0 0 2.5" />
            <geometry>
                <cylinder length="5" radius="1.5" />
            </geometry>
        </collision>
        <visual>
            <origin rpy="0 0 0" xyz="0 0 2.5" />
            <geometry>
                <cylinder length="5" radius="1.5" />
            </geometry>
        </visual>
        <material name="red">
            <color rgba="0.8 0.0 0.0 1.0" />
        </material>
        
<inertial>
            <mass value="0.1" />
            <inertia ixx="0.03" iyy="0.03" izz="0.03" ixy="0.0" ixz="0.0" iyz="0.0" />
        </inertial>

    </link>
    <joint name="joint1_base_link_to_link1" type="prismatic">
        <origin rpy="0 0 0" xyz="0 0 1" />
        <parent link="base_link" />
        <child link="link1" />
        <axis xyz="0 0 1" />
        <limit effort="1000" lower="0" upper="4.0" velocity="0.5" />
    </joint>
    <link name="link1">
        <collision>
            <origin rpy="0 0 0" xyz="0 0 2.5" />
            <geometry>
                <cylinder length="5" radius="1" />
            </geometry>
        </collision>
        <visual>
            <origin rpy="0 0 0" xyz="0 0 2.5" />
            <geometry>
                <cylinder length="5" radius="1" />
            </geometry>
        </visual>
        <material name="green">
            <color rgba="0.0 0.8 0.0 1.0" />
        </material>
        
<inertial>
            <mass value="0.1" />
            <inertia ixx="0.03" iyy="0.03" izz="0.03" ixy="0.0" ixz="0.0" iyz="0.0" />
        </inertial>

    </link>
    <joint name="joint2_link1_to_link2" type="revolute">
        <origin rpy="0 0 0" xyz="0 0 0" />
        <parent link="link1" />
        <child link="link2" />
        <axis xyz="0 0 1" />
        <limit effort="1000" lower="-3.14" upper="3.14" velocity="1.0" />
    </joint>
    <link name="link2">
        <visual>
            <origin rpy="0 0 0" xyz="2.5 0 5.5" />
            <geometry>
                <box size="5 1 1" />
            </geometry>
        </visual>
        <collision>
            <origin rpy="0 0 0" xyz="2.5 0 5.5" />
            <geometry>
                <box size="5 1 1" />
            </geometry>
        </collision>
        <material name="red">
            <color rgba="0.8 0.0 0.0 1.0" />
        </material>
        
<inertial>
            <mass value="0.1" />
            <inertia ixx="0.03" iyy="0.03" izz="0.03" ixy="0.0" ixz="0.0" iyz="0.0" />
        </inertial>

    </link>
    <joint name="joint3_link2_to_hand" type="fixed">
        <origin rpy="0 0 0" xyz="0 0 0" />
        <parent link="link2" />
        <child link="hand" />
        <axis xyz="0 0 0" />
        <limit effort="0" lower="0" upper="0" velocity="0" />
    </joint>
    <link name="hand">
        <visual>
            <origin rpy="0 0 0" xyz="5.5 0 5.5" />
            <geometry>
                <box size="1 1 1" />
            </geometry>
        </visual>
        <collision>
            <origin rpy="0 0 0" xyz="5.5 0 5.5" />
            <geometry>
                <box size="1 1 1" />
            </geometry>
        </collision>
        <material name="green">
            <color rgba="0.0 0.8 0.0 1.0" />
        </material>
        
<inertial>
            <mass value="0.1" />
            <inertia ixx="0.03" iyy="0.03" izz="0.03" ixy="0.0" ixz="0.0" iyz="0.0" />
        </inertial>

    </link>
    
<transmission name="trans_joint1_base_link_to_link1">
        <type>transmission_interface/SimpleTransmission</type>
        <joint name="joint1_base_link_to_link1">
            <hardwareInterface>hardware_interface/EffortJointInterface</hardwareInterface>
        </joint>
        <actuator name="joint1_base_link_to_link1_motor">
            <hardwareInterface>hardware_interface/EffortJointInterface</hardwareInterface>
            <mechanicalReduction>1</mechanicalReduction>
        </actuator>
    </transmission>
    <transmission name="trans_joint2_link1_to_link2">
        <type>transmission_interface/SimpleTransmission</type>
        <joint name="joint2_link1_to_link2">
            <hardwareInterface>hardware_interface/EffortJointInterface</hardwareInterface>
        </joint>
        <actuator name="joint2_link1_to_link2_motor">
            <hardwareInterface>hardware_interface/EffortJointInterface</hardwareInterface>
            <mechanicalReduction>1</mechanicalReduction>
        </actuator>
    </transmission>
    <gazebo>
        <plugin name="gazebo_ros_control" filename="libgazebo_ros_control.so">
            <robotNamespace>/</robotNamespace>
        </plugin>
    </gazebo>
</robot>